<?xml version="1.0" ?>
<!-- =================================================================================== -->
<!-- |    This document was autogenerated by xacro from rv4fl.urdf.xacro               | -->
<!-- |    EDITING THIS FILE BY HAND IS NOT RECOMMENDED                                 | -->
<!-- =================================================================================== -->
<!-- Copyright (C) 2018, Tokyo Opensource Robotics Kyokai Association -->
<robot name="rv4fl">
  <material name="white">
    <color rgba="1.0 1.0 1.0 1.0"/>
  </material>
  <link name="base_link"/>
  <joint name="rv4fl_mounting_joint" type="fixed">
    <origin rpy="0 0 0" xyz="0 0 0"/>
    <parent link="base_link"/>
    <child link="link0"/>
  </joint>
  <link name="link0">
    <visual>
      <origin rpy="0 0 3.141592653589793" xyz="0 0 0"/>
      <geometry>
        <mesh filename="package://melfa_description/mesh/rv4fl/L0.stl"/>
      </geometry>
      <material name="white"/>
    </visual>
    <collision>
      <origin rpy="0 0 3.141592653589793" xyz="0 0 0"/>
      <geometry>
        <mesh filename="package://melfa_description/mesh/rv4fl/L0.stl"/>
      </geometry>
    </collision>
    <inertial>
      <origin rpy="0 0 0" xyz="0 0 0"/>
      <mass value="1"/>
      <inertia ixx="3.5e-05" ixy="0" ixz="-4e-06" iyy="5.2e-05" iyz="0" izz="4.9e-05"/>
    </inertial>
  </link>
  <joint name="joint1" type="revolute">
    <parent link="link0"/>
    <child link="link1"/>
    <origin rpy="0 0 0" xyz="0 0 0.350"/>
    <axis xyz="0 0 1"/>
    <dynamics damping="0.7"/>
    <limit effort="224.64" lower="-4.1887902047863905" upper="4.1887902047863905" velocity="7.330"/>
  </joint>
  <link name="link1">
    <visual>
      <origin rpy="0 0 0" xyz="0 0 -0.350"/>
      <geometry>
        <mesh filename="package://melfa_description/mesh/rv4fl/L1.stl"/>
      </geometry>
      <material name="white"/>
    </visual>
    <collision>
      <origin rpy="0 0 0" xyz="0 0 -0.350"/>
      <geometry>
        <mesh filename="package://melfa_description/mesh/rv4fl/L1.stl"/>
      </geometry>
    </collision>
    <inertial>
      <origin rpy="0 0 0" xyz="0 0 0"/>
      <mass value="1"/>
      <inertia ixx="3.4e-05" ixy="0" ixz="1e-06" iyy="2.5e-05" iyz="0" izz="2.5e-05"/>
    </inertial>
  </link>
  <joint name="joint2" type="revolute">
    <parent link="link1"/>
    <child link="link2"/>
    <origin rpy="0 0 0" xyz="0 0 0"/>
    <axis xyz="0 1 0"/>
    <dynamics damping="0.7"/>
    <limit effort="263.25" lower="-1.9198621771937625" upper="2.2689280275926285" velocity="5.602506898901797"/>
  </joint>
  <link name="link2">
    <visual>
      <origin rpy="0 0 3.141592653589793" xyz="0 0 -0.350"/>
      <geometry>
        <mesh filename="package://melfa_description/mesh/rv4fl/L2.stl"/>
      </geometry>
      <material name="white"/>
    </visual>
    <collision>
      <origin rpy="0 0 3.141592653589793" xyz="0 0 -0.350"/>
      <geometry>
        <mesh filename="package://melfa_description/mesh/rv4fl/L2.stl"/>
      </geometry>
    </collision>
    <inertial>
      <origin rpy="0 0 0" xyz="0 0 0"/>
      <mass value="1"/>
      <inertia ixx="6.9e-05" ixy="0" ixz="-3e-06" iyy="6.4e-05" iyz="0" izz="1.8e-05"/>
    </inertial>
  </link>
  <joint name="joint3" type="revolute">
    <parent link="link2"/>
    <child link="link3"/>
    <origin rpy="0 0 0" xyz="0 0 0.310"/>
    <axis xyz="0 1 0"/>
    <dynamics damping="0.7"/>
    <limit effort="145.15" lower="0.00" upper="2.827433388230814" velocity="6.283185307179586"/>
  </joint>
  <link name="link3">
    <visual>
      <origin rpy="0 0 3.141592653589793" xyz="0 0 -0.6599999999999999"/>
      <geometry>
        <mesh filename="package://melfa_description/mesh/rv4fl/L3.stl"/>
      </geometry>
      <material name="white"/>
    </visual>
    <collision>
      <origin rpy="0 0 3.141592653589793" xyz="0 0 -0.6599999999999999"/>
      <geometry>
        <mesh filename="package://melfa_description/mesh/rv4fl/L3.stl"/>
      </geometry>
    </collision>
    <inertial>
      <origin rpy="0 0 0" xyz="0 0 0"/>
      <mass value="1"/>
      <inertia ixx="6e-06" ixy="0" ixz="0" iyy="7e-06" iyz="0" izz="6e-06"/>
    </inertial>
  </link>
  <joint name="joint4" type="revolute">
    <parent link="link3"/>
    <child link="link4"/>
    <origin rpy="0 0 0" xyz="-0.050 0 0.335"/>
    <axis xyz="0 0 1"/>
    <dynamics damping="0.7"/>
    <limit effort="10" lower="-3.490658503988659" upper="3.490658503988659" velocity="5.88175957922089"/>
  </joint>
  <link name="link4">
    <visual>
      <origin rpy="0 0 0" xyz="-0.050 0 -0.9949999999999999"/>
      <geometry>
        <mesh filename="package://melfa_description/mesh/rv4fl/L4.stl"/>
      </geometry>
      <material name="white"/>
    </visual>
    <collision>
      <origin rpy="0 0 0" xyz="-0.050 0 -0.9949999999999999"/>
      <geometry>
        <mesh filename="package://melfa_description/mesh/rv4fl/L4.stl"/>
      </geometry>
    </collision>
    <inertial>
      <origin rpy="0 0 0" xyz="0 0 0"/>
      <mass value="1"/>
      <inertia ixx="1.9e-05" ixy="0" ixz="0.0" iyy="1.7e-05" iyz="0" izz="4e-06"/>
    </inertial>
  </link>
  <joint name="joint5" type="revolute">
    <parent link="link4"/>
    <child link="link5"/>
    <origin rpy="0 0 0" xyz="0 0 0"/>
    <axis xyz="0 1 0"/>
    <dynamics damping="0.7"/>
    <limit effort="10" lower="-2.0943951023931953" upper="2.0943951023931953" velocity="7.853981633974483"/>
  </joint>
  <link name="link5">
    <visual>
      <origin rpy="0 0 0" xyz="-0.050 0 -0.9949999999999999"/>
      <geometry>
        <mesh filename="package://melfa_description/mesh/rv4fl/L5.stl"/>
      </geometry>
      <material name="white"/>
    </visual>
    <collision>
      <origin rpy="0 0 0" xyz="-0.050 0 -0.9949999999999999"/>
      <geometry>
        <mesh filename="package://melfa_description/mesh/rv4fl/L5.stl"/>
      </geometry>
    </collision>
    <inertial>
      <origin rpy="0 0 0" xyz="0 0 0"/>
      <mass value="1"/>
      <inertia ixx="1e-06" ixy="0" ixz="0.0" iyy="1e-06" iyz="0" izz="1e-06"/>
    </inertial>
  </link>
  <joint name="joint6" type="revolute">
    <parent link="link5"/>
    <child link="link6"/>
    <origin rpy="0 0 0" xyz="0 0 0.125"/>
    <axis xyz="0 0 1"/>
    <dynamics damping="0.7"/>
    <limit effort="10" lower="-6.283185307179586" upper="6.283185307179586" velocity="12.566370614359172"/>
  </joint>
  <link name="link6">
    <visual>
      <origin rpy="0 0 0" xyz="-0.050 0 -1.1199999999999999"/>
      <geometry>
        <mesh filename="package://melfa_description/mesh/rv4fl/L6.stl"/>
      </geometry>
      <material name="white"/>
    </visual>
    <collision>
      <origin rpy="0 0 0" xyz="-0.050 0 -1.1199999999999999"/>
      <geometry>
        <mesh filename="package://melfa_description/mesh/rv4fl/L6.stl"/>
      </geometry>
    </collision>
    <inertial>
      <origin rpy="0 0 0" xyz="0 0 0"/>
      <mass value="1"/>
      <inertia ixx="1e-06" ixy="0" ixz="0.0" iyy="1e-06" iyz="0" izz="1e-06"/>
    </inertial>
  </link>
  <gazebo reference="link0">
    <material>Gazebo/White</material>
    <mu1>0.2</mu1>
    <mu2>0.2</mu2>
  </gazebo>
  <gazebo reference="link1">
    <material>Gazebo/White</material>
    <mu1>0.2</mu1>
    <mu2>0.2</mu2>
  </gazebo>
  <gazebo reference="link2">
    <material>Gazebo/White</material>
    <mu1>0.2</mu1>
    <mu2>0.2</mu2>
  </gazebo>
  <gazebo reference="link3">
    <material>Gazebo/White</material>
    <mu1>0.2</mu1>
    <mu2>0.2</mu2>
  </gazebo>
  <gazebo reference="link4">
    <material>Gazebo/White</material>
    <mu1>0.2</mu1>
    <mu2>0.2</mu2>
  </gazebo>
  <gazebo reference="link5">
    <material>Gazebo/White</material>
    <mu1>0.2</mu1>
    <mu2>0.2</mu2>
  </gazebo>
  <gazebo reference="link6">
    <material>Gazebo/White</material>
    <mu1>0.2</mu1>
    <mu2>0.2</mu2>
  </gazebo>
  <transmission name="tran_1">
    <type>transmission_interface/SimpleTransmission</type>
    <joint name="joint1">
      <hardwareInterface>hardware_interface/PositionJointInterface</hardwareInterface>
    </joint>
    <actuator name="motor_1">
      <hardwareInterface>hardware_interface/PositionJointInterface</hardwareInterface>
      <mechanicalReduction>1</mechanicalReduction>
    </actuator>
  </transmission>
  <transmission name="tran_2">
    <type>transmission_interface/SimpleTransmission</type>
    <joint name="joint2">
      <hardwareInterface>hardware_interface/PositionJointInterface</hardwareInterface>
    </joint>
    <actuator name="motor_2">
      <hardwareInterface>hardware_interface/PositionJointInterface</hardwareInterface>
      <mechanicalReduction>1</mechanicalReduction>
    </actuator>
  </transmission>
  <transmission name="tran_3">
    <type>transmission_interface/SimpleTransmission</type>
    <joint name="joint3">
      <hardwareInterface>hardware_interface/PositionJointInterface</hardwareInterface>
    </joint>
    <actuator name="motor_3">
      <hardwareInterface>hardware_interface/PositionJointInterface</hardwareInterface>
      <mechanicalReduction>1</mechanicalReduction>
    </actuator>
  </transmission>
  <transmission name="tran_4">
    <type>transmission_interface/SimpleTransmission</type>
    <joint name="joint4">
      <hardwareInterface>hardware_interface/PositionJointInterface</hardwareInterface>
    </joint>
    <actuator name="motor_4">
      <hardwareInterface>hardware_interface/PositionJointInterface</hardwareInterface>
      <mechanicalReduction>1</mechanicalReduction>
    </actuator>
  </transmission>
  <transmission name="tran_5">
    <type>transmission_interface/SimpleTransmission</type>
    <joint name="joint5">
      <hardwareInterface>hardware_interface/PositionJointInterface</hardwareInterface>
    </joint>
    <actuator name="motor_5">
      <hardwareInterface>hardware_interface/PositionJointInterface</hardwareInterface>
      <mechanicalReduction>1</mechanicalReduction>
    </actuator>
  </transmission>
  <transmission name="tran_6">
    <type>transmission_interface/SimpleTransmission</type>
    <joint name="joint6">
      <hardwareInterface>hardware_interface/PositionJointInterface</hardwareInterface>
    </joint>
    <actuator name="motor_6">
      <hardwareInterface>hardware_interface/PositionJointInterface</hardwareInterface>
      <mechanicalReduction>1</mechanicalReduction>
    </actuator>
  </transmission>
  <gazebo>
    <plugin filename="libgazebo_ros_control.so" name="gazebo_ros_control"/>
  </gazebo>
</robot>

