<?xml version="1.0" ?>
<!-- =================================================================================== -->
<!-- |    This document was autogenerated by xacro from /home/bartek/inzynierka_1/src/melfa_robot/melfa_description/urdf/rv4fl.urdf.xacro | -->
<!-- |    EDITING THIS FILE BY HAND IS NOT RECOMMENDED                                 | -->
<!-- =================================================================================== -->
<!-- Copyright (C) 2018, Tokyo Opensource Robotics Kyokai Association -->
<robot name="rv4fl">
    <material name="white">
        <color rgba="1.0 1.0 1.0 1.0" />
    </material>
    <link name="base_link" />
    <joint name="rv4fl_mounting_joint" type="fixed">
        <origin rpy="0 0 0" xyz="0 0 0" />
        <parent link="base_link" />
        <child link="link0" />
    </joint>
    <link name="link0">
        <visual>
            <origin rpy="0 0 3.141592653589793" xyz="0 0 0" />
            <geometry>
                <mesh filename="package://melfa_description/mesh/rv4fl/L0.stl" />
            </geometry>
            <material name="white" />
        </visual>
        <collision>
            <origin rpy="0 0 3.141592653589793" xyz="0 0 0" />
            <geometry>
                <mesh filename="package://melfa_description/mesh/rv4fl/L0.stl" />
            </geometry>
        </collision>
        <inertial>
            <mass value="0.1" />
            <origin xyz="0 0 0" rpy="0 0 0" />
            <inertia ixx="0.03" iyy="0.03" izz="0.03" ixy="0.0" ixz="0.0" iyz="0.0" />
        </inertial>
    </link>
    <joint name="joint1" type="revolute">
        <parent link="link0" />
        <child link="link1" />
        <origin rpy="0 0 0" xyz="0 0 0.350" />
        <axis xyz="0 0 1" />
        <dynamics damping="0.7" />
        <limit effort="224.64" lower="-4.1887902047863905" upper="4.1887902047863905" velocity="7.330" />
    </joint>
    <link name="link1">
        <visual>
            <origin rpy="0 0 0" xyz="0 0 -0.350" />
            <geometry>
                <mesh filename="package://melfa_description/mesh/rv4fl/L1.stl" />
            </geometry>
            <material name="white" />
        </visual>
        <collision>
            <origin rpy="0 0 0" xyz="0 0 -0.350" />
            <geometry>
                <mesh filename="package://melfa_description/mesh/rv4fl/L1.stl" />
            </geometry>
        </collision>
        <inertial>
            <mass value="0.1" />
            <origin xyz="0 0 0" rpy="0 0 0" />
            <inertia ixx="0.03" iyy="0.03" izz="0.03" ixy="0.0" ixz="0.0" iyz="0.0" />
        </inertial>
    </link>
    <joint name="joint2" type="revolute">
        <parent link="link1" />
        <child link="link2" />
        <origin rpy="0 0 0" xyz="0 0 0" />
        <axis xyz="0 1 0" />
        <dynamics damping="0.7" />
        <limit effort="263.25" lower="-1.9198621771937625" upper="2.2689280275926285" velocity="5.602506898901797" />
    </joint>
    <link name="link2">
        <visual>
            <origin rpy="0 0 3.141592653589793" xyz="0 0 -0.350" />
            <geometry>
                <mesh filename="package://melfa_description/mesh/rv4fl/L2.stl" />
            </geometry>
            <material name="white" />
        </visual>
        <collision>
            <origin rpy="0 0 3.141592653589793" xyz="0 0 -0.350" />
            <geometry>
                <mesh filename="package://melfa_description/mesh/rv4fl/L2.stl" />
            </geometry>
        </collision>
        <inertial>
            <mass value="0.1" />
            <origin xyz="0 0 0" rpy="0 0 0" />
            <inertia ixx="0.03" iyy="0.03" izz="0.03" ixy="0.0" ixz="0.0" iyz="0.0" />
        </inertial>
    </link>
    <joint name="joint3" type="revolute">
        <parent link="link2" />
        <child link="link3" />
        <origin rpy="0 0 0" xyz="0 0 0.310" />
        <axis xyz="0 1 0" />
        <dynamics damping="0.7" />
        <limit effort="145.15" lower="0.00" upper="2.827433388230814" velocity="6.283185307179586" />
    </joint>
    <link name="link3">
        <visual>
            <origin rpy="0 0 3.141592653589793" xyz="0 0 -0.6599999999999999" />
            <geometry>
                <mesh filename="package://melfa_description/mesh/rv4fl/L3.stl" />
            </geometry>
            <material name="white" />
        </visual>
        <collision>
            <origin rpy="0 0 3.141592653589793" xyz="0 0 -0.6599999999999999" />
            <geometry>
                <mesh filename="package://melfa_description/mesh/rv4fl/L3.stl" />
            </geometry>
        </collision>
        <inertial>
            <mass value="0.1" />
            <origin xyz="0 0 0" rpy="0 0 0" />
            <inertia ixx="0.03" iyy="0.03" izz="0.03" ixy="0.0" ixz="0.0" iyz="0.0" />
        </inertial>
    </link>
    <joint name="joint4" type="revolute">
        <parent link="link3" />
        <child link="link4" />
        <origin rpy="0 0 0" xyz="-0.050 0 0.335" />
        <axis xyz="0 0 1" />
        <dynamics damping="0.7" />
        <limit effort="10" lower="-3.490658503988659" upper="3.490658503988659" velocity="5.88175957922089" />
    </joint>
    <link name="link4">
        <visual>
            <origin rpy="0 0 0" xyz="-0.050 0 -0.9949999999999999" />
            <geometry>
                <mesh filename="package://melfa_description/mesh/rv4fl/L4.stl" />
            </geometry>
            <material name="white" />
        </visual>
        <collision>
            <origin rpy="0 0 0" xyz="-0.050 0 -0.9949999999999999" />
            <geometry>
                <mesh filename="package://melfa_description/mesh/rv4fl/L4.stl" />
            </geometry>
        </collision>
        <inertial>
            <mass value="0.1" />
            <origin xyz="0 0 0" rpy="0 0 0" />
            <inertia ixx="0.03" iyy="0.03" izz="0.03" ixy="0.0" ixz="0.0" iyz="0.0" />
        </inertial>
    </link>
    <joint name="joint5" type="revolute">
        <parent link="link4" />
        <child link="link5" />
        <origin rpy="0 0 0" xyz="0 0 0" />
        <axis xyz="0 1 0" />
        <dynamics damping="0.7" />
        <limit effort="10" lower="-2.0943951023931953" upper="2.0943951023931953" velocity="7.853981633974483" />
    </joint>
    <link name="link5">
        <visual>
            <origin rpy="0 0 0" xyz="-0.050 0 -0.9949999999999999" />
            <geometry>
                <mesh filename="package://melfa_description/mesh/rv4fl/L5.stl" />
            </geometry>
            <material name="white" />
        </visual>
        <collision>
            <origin rpy="0 0 0" xyz="-0.050 0 -0.9949999999999999" />
            <geometry>
                <mesh filename="package://melfa_description/mesh/rv4fl/L5.stl" />
            </geometry>
        </collision>
        <inertial>
            <mass value="0.1" />
            <origin xyz="0 0 0" rpy="0 0 0" />
            <inertia ixx="0.03" iyy="0.03" izz="0.03" ixy="0.0" ixz="0.0" iyz="0.0" />
        </inertial>
    </link>
    <joint name="joint6" type="revolute">
        <parent link="link5" />
        <child link="link6" />
        <origin rpy="0 0 0" xyz="0 0 0.125" />
        <axis xyz="0 0 1" />
        <dynamics damping="0.7" />
        <limit effort="10" lower="-6.283185307179586" upper="6.283185307179586" velocity="12.566370614359172" />
    </joint>
    <link name="link6">
        <visual>
            <origin rpy="0 0 0" xyz="-0.050 0 -1.1199999999999999" />
            <geometry>
                <mesh filename="package://melfa_description/mesh/rv4fl/L6.stl" />
            </geometry>
            <material name="white" />
        </visual>
        <collision>
            <origin rpy="0 0 0" xyz="-0.050 0 -1.1199999999999999" />
            <geometry>
                <mesh filename="package://melfa_description/mesh/rv4fl/L6.stl" />
            </geometry>
        </collision>
        <inertial>
            <mass value="0.1" />
            <origin xyz="0 0 0" rpy="0 0 0" />
            <inertia ixx="0.03" iyy="0.03" izz="0.03" ixy="0.0" ixz="0.0" iyz="0.0" />
        </inertial>
    </link>
    <transmission name="trans_joint1">
        <type>transmission_interface/SimpleTransmission</type>
        <joint name="joint1">
            <hardwareInterface>hardware_interface/EffortJointInterface</hardwareInterface>
        </joint>
        <actuator name="joint1_motor">
            <hardwareInterface>hardware_interface/EffortJointInterface</hardwareInterface>
            <mechanicalReduction>1</mechanicalReduction>
        </actuator>
    </transmission>
    <transmission name="trans_joint2">
        <type>transmission_interface/SimpleTransmission</type>
        <joint name="joint2">
            <hardwareInterface>hardware_interface/EffortJointInterface</hardwareInterface>
        </joint>
        <actuator name="joint2_motor">
            <hardwareInterface>hardware_interface/EffortJointInterface</hardwareInterface>
            <mechanicalReduction>1</mechanicalReduction>
        </actuator>
    </transmission>
    <transmission name="trans_joint3">
        <type>transmission_interface/SimpleTransmission</type>
        <joint name="joint3">
            <hardwareInterface>hardware_interface/EffortJointInterface</hardwareInterface>
        </joint>
        <actuator name="joint3_motor">
            <hardwareInterface>hardware_interface/EffortJointInterface</hardwareInterface>
            <mechanicalReduction>1</mechanicalReduction>
        </actuator>
    </transmission>
    <transmission name="trans_joint4">
        <type>transmission_interface/SimpleTransmission</type>
        <joint name="joint4">
            <hardwareInterface>hardware_interface/EffortJointInterface</hardwareInterface>
        </joint>
        <actuator name="joint4_motor">
            <hardwareInterface>hardware_interface/EffortJointInterface</hardwareInterface>
            <mechanicalReduction>1</mechanicalReduction>
        </actuator>
    </transmission>
    <transmission name="trans_joint5">
        <type>transmission_interface/SimpleTransmission</type>
        <joint name="joint5">
            <hardwareInterface>hardware_interface/EffortJointInterface</hardwareInterface>
        </joint>
        <actuator name="joint5_motor">
            <hardwareInterface>hardware_interface/EffortJointInterface</hardwareInterface>
            <mechanicalReduction>1</mechanicalReduction>
        </actuator>
    </transmission>
    <transmission name="trans_joint6">
        <type>transmission_interface/SimpleTransmission</type>
        <joint name="joint6">
            <hardwareInterface>hardware_interface/EffortJointInterface</hardwareInterface>
        </joint>
        <actuator name="joint6_motor">
            <hardwareInterface>hardware_interface/EffortJointInterface</hardwareInterface>
            <mechanicalReduction>1</mechanicalReduction>
        </actuator>
    </transmission>
    <gazebo>
        <plugin name="gazebo_ros_control">
            <robotNamespace>/</robotNamespace>
        </plugin>
    </gazebo>
</robot>

